Workbook

Sheet Calculator
A1: Convert From SLPM (N2) to velocity | G1: Constants:
B2: SLPM (N2) | C2: Velocity cm/s | E2: Conv Factor | G2: Temperature [C] | H2: 22
A3: Coflow/MFCA1 | B3: 5.368 | C3: =B3*$E$3 -> 19.795482 | E3: =$H$9/$H$3/$H$7/$H$4*$H$5/$H$6 -> 3.687683 | G3: Temperature Factor | H3: =(273.15/(273.15+H2)) -> 0.92546163
A4: Dilution/MFCA2 | B4: 0.01006198 | C4: =B4*$E$4 -> 4.2393127 | E4: =$H$3/$H$8/$H$4*$H$5/$H$6 -> 421.31993 | G4: seconds/min | H4: 60
A5: Fuel/MFCA3 | B5: 0.1 | C5: =B5*$E$5 -> 38.305871 | E5: =$H$11/$H$3/$H$8/$H$4*$H$5/$H$6 -> 383.05871 | G5: cm3 / liter | H5: 1000
G6: cm2 / m2 | H6: 10000
G7: Outer Coflow Area [m2] | H7: =VLOOKUP(B21,Tables!D36:H43,5,FALSE) -> 0.00048604952
G8: Burner area [m2] | H8: =VLOOKUP(B21,Tables!D36:H43,3,FALSE) -> 3.6609615e-06
A9: Convert from velocity to SLPM (N2) | G9: Coflow Gas Correction Factor | H9: =VLOOKUP(B17,Tables!$B$22:$K$26,10,FALSE) -> 0.99527653
B10: Velocity cm/s | C10: SLPM (N2) | G10: Dilution Gas Correction Factor | H10: =VLOOKUP(B18,Tables!B27:K28,10,FALSE) -> 1
A11: Coflow/MFCA1 | B11: 19.79 | C11: =B11/$E$3 -> 5.3665134 | G11: Fuel Gas Correction Factor | H11: =VLOOKUP(B19,Tables!B3:K21,10,FALSE) -> 0.7787
A12: Dilution/MFCA2 | B12: 4.95 | C12: =B12/$E$4 -> 0.011748792
A13: Fuel/MFCA3 | B13: 10 | C13: =B13/$E$5 -> 0.026105659
B16: Choose:
A17: Coflow/MFCA1 Gas T ype | B17: Oxygen/Nitrogen (21/79)
A18: Dilution/MFCA2 Gas Type | B18: Nitrogen
A19: Fuel/MFCA3 Gas Type | B19: Methane
A21: Burner Type | B21: Coflow

Sheet HeaderTables
A1: Experiment Type
A2: 0 | B2: Flame Design
A3: 1 | B3: Coflow
A4: 2 | B4: S-Flame
A5: 3 | B5: E-Field
A6: 4 | B6: BRE
A8: MFCA1 Gas Type
A9: 0 | B9: Oxygen/Nitrogen (21/79)
A10: 1 | B10: Oxygen/Nitrogen (30/70)
A11: 2 | B11: Oxygen/Nitrogen (40/60)
A12: 3 | B12: Oxygen/Nitrogen (85/15)
A13: 4 | B13: Oxygen/Helium (30/70)
A15: MFCA2 Gas Type
A16: 0 | B16: Nitrogen
A17: 1 | B17: Helium
A19: MFCA3 Gas Type
A20: 0 | B20: Methane
A21: 1 | B21: Methane/Nitrogen (30/70)
A22: 2 | B22: Methane/Nitrogen (40/60)
A23: 3 | B23: Methane/Nitrogen (45/55)
A24: 4 | B24: Ethylene
A25: 5 | B25: Ethylene/Nitrogen (30/70)
A26: 6 | B26: Ethylene/Nitrogen (50/50)
A27: 7 | B27: Hydrogen
A28: 8 | B28: Hydrogen/Methane (44.4/55.6)
A29: 9 | B29: Hydrogen/Methane (55.6/44.4)
A30: 10 | B30: Hydrogen/Methane (66.7/33.3)
A31: 11 | B31: Hydrogen/Methane/Helium (20/25/55)
... A38: 18 | B38: Ethylene/Helium (30/70)
A41: EField Config
A42: 0 | B42: Mesh Removed
A43: 1 | B43: Mesh in 35 mm position
A44: 2 | B44: Mesh in 40 mm position
A46: EField Polarity
A47: 0 | B47: Not installed
A48: 1 | B48: Negative
A49: 2 | B49: Positive
A51: Igniter Arm Position
A52: 0 | B52: 0 mm
A53: 1 | B53: 10 mm
...

Sheet Tables
A1: Enum | B1: Name | C1: Gas Bottle | D1: Manifold | E1: First Gas | G1: Second Gas | I1: Third Gas | K1: Mixture Gas
E2: Conc | F2: GCF | G2: Conc | H2: GCF | I2: Conc | J2: GCF | K2: Correction Factor
A3: 0 | B3: Methane | C3: CH4 100% | D3: 4 - Fuel | E3: 1 | F3: 0.7787 | G3: 0 | H3: 99 | I3: 0 | J3: 99 | K3: =1/(E3/F3+G3/H3+I3/J3) -> 0.7787
A4: 1 | B4: Methane/Nitrogen (30/70) | C4: CH4/N2 30/70% | D4: 4 - Fuel | E4: 0.3 | F4: 0.7787 | G4: 0.7 | H4: 1 | I4: 0 | J4: 99 | K4: =1/(E4/F4+G4/H4+I4/J4) -> 0.92144032
A5: 2 | B5: Methane/Nitrogen (40/60) | C5: CH4/N2 40/60% | D5: 4 - Fuel | E5: 0.4 | F5: 0.7787 | G5: 0.6 | H5: 1 | I5: 0 | J5: 99 | K5: =1/(E5/F5+G5/H5+I5/J5) -> 0.89792671
A6: 3 | B6: Methane/Nitrogen (45/55) | C6: CH4/N2 45/55% | D6: 4 - Fuel | E6: 0.45 | F6: 0.7787 | G6: 0.55 | H6: 1 | I6: 0 | J6: 99 | K6: =1/(E6/F6+G6/H6+I6/J6) -> 0.88661425
A7: 4 | B7: Ethylene | C7: C2H4 100% | D7: 4 - Fuel | E7: 1 | F7: 0.6062 | G7: 0 | H7: 99 | I7: 0 | J7: 99 | K7: =1/(E7/F7+G7/H7+I7/J7) -> 0.6062
A8: 5 | B8: Ethylene/Nitrogen (30/70) | C8: C2H4/N2 30/70% | D8: 4 - Fuel | E8: 0.3 | F8: 0.6062 | G8: 0.7 | H8: 1 | I8: 0 | J8: 99 | K8: =1/(E8/F8+G8/H8+I8/J8) -> 0.8368998
A9: 6 | B9: Ethylene/Nitrogen (50/50) | C9: C2H4/N2 50/50% | D9: 4 - Fuel | E9: 0.5 | F9: 0.6062 | G9: 0.5 | H9: 1 | I9: 0 | J9: 99 | K9: =1/(E9/F9+G9/H9+I9/J9) -> 0.75482505
A10: 7 | B10: Hydrogen | C10: H2 100% | D10: 4 - Fuel | E10: 1 | F10: 1.0038 | G10: 0 | H10: 99 | I10: 0 | J10: 99 | K10: =1/(E10/F10+G10/H10+I10/J10) -> 1.0038
A11: 8 | B11: Hydrogen/Methane (44.4/55.6) | C11: H2/CH4 44.4/55.6% | D11: 4 - Fuel | E11: 0.444 | F11: 1.0038 | G11: 0.556 | H11: 0.7787 | I11: 0 | J11: 99 | K11: =1/(E11/F11+G11/H11+I11/J11) -> 0.86480524
A12: 9 | B12: Hydrogen/Methane (55.6/44.4) | C12: H2/CH4 55.6/44.4% | D12: 4 - Fuel | E12: 0.556 | F12: 1.0038 | G12: 0.444 | H12: 0.7787 | I12: 0 | J12: 99 | K12: =1/(E12/F12+G12/H12+I12/J12) -> 0.88961935
A13: 10 | B13: Hydrogen/Methane (66.7/33.3) | C13: H2/CH4 66.7/33.3% | D13: 4 - Fuel | E13: 0.667 | F13: 1.0038 | G13: 0.333 | H13: 0.7787 | I13: 0 | J13: 99 | K13: =1/(E13/F13+G13/H13+I13/J13) -> 0.91565801
A14: 11 | B14: Hydrogen/Methane/Helium (20/25/55) | C14: H2/CH4/He 20/25/55% | D14: 4 - Fuel | E14: 0.2 | F14: 1.0038 | G14: 0.25 | H14: 0.7787 | I14: 0.55 | J14: 99 | K14: =1/(E14/F14+G14/H14+I14/J14) -> 1.9016963
... A26: 4 | B26: Oxygen/Helium (30/70) | C26: O2/He 30/70% | D26: 2 - Oxygen | E26: 0.3 | F26: 0.9779 | G26: 0.7 | H26: 1.4005 | I26: 0 | J26: 99 | K26: =1/(E26/F26+G26/H26+I26/J26) -> 1.2397698
A27: 0 | B27: Nitrogen | C27: N2 100% | D27: 1 - Diluent | E27: 1 | F27: 1 | K27: 1
A28: 1 | B28: Helium | C28: He 100% | D28: 1 - Diluent | E28: 1 | F28: 1.4005 | G28: 0 | H28: 99 | I28: 0 | J28: 99 | K28: =1/(E28/F28+G28/H28+I28/J28) -> 1.4005
A29: 99 means n/a
A31: Temperature C | B31: 22
A32: Temperature Factor | B32: =(273.15/(273.15+B31)) -> 0.92546163
A33: seconds/min | B33: 60
A34: cm3 / liter | B34: 1000
A35: cm2 / m2 | B35: 10000 | D35: Burner Areas (m2)
D36: Spherical (1/4") | F36: 1 | H36: 0
D37: Spherical (3/8") | F37: 1 | H37: 0
D38: Spherical (1/2") | F38: 1 | H38: 0
D39: Coflow | E39: Inner | F39: =PI()/4*((0.085*0.0254)^2) -> 3.6609615e-06 | G39: Outer | H39: =((PI()/4*((0.984*0.0254)^2))-((PI()/4*((0.095*0.0254)^2)))) -> 0.00048604952
D40: Gas Jet(1.3mm) | F40: =PI()/4*((1.3*0.001)^2) -> 1.3273229e-06 | H40: 0
D41: Gas Jet(2.1mm) | F41: =PI()/4*((2.1*0.001)^2) -> 3.4636059e-06 | H41: 0
D42: BRE 25mm | F42: =PI()/4*((25*0.001)^2) -> 0.00049087385 | H42: 0
D43: BRE 50mm | F43: =PI()/4*((50*0.001)^2) -> 0.0019634954 | H43: 0
